Workbook

Sheet Raw DataSet
A1: Attrition | B1: Business Travel | C1: CF_age band | D1: CF_attrition label | E1: CF_current Employee | F1: Department | G1: Education Field | H1: emp no | I1: Employee Number | J1: Gender | K1: Job Role | L1: Marital Status | M1: Over Time | N1: Over18 | O1: Training Times Last Year | P1: Age | Q1: Distance From Home | R1: Education | S1: Employee Count | T1: Environment Satisfaction | U1: Hourly Income | V1: Standard Weekly Working Hours | W1: Monthly Income | X1: Income Band | Y1: Job Involvement | Z1: Job Level | AA1: Job Satisfaction | AB1: Num Companies Worked | AC1: Percent Salary Hike | AD1: Performance Rating | AE1: Relationship Satisfaction | AF1: Stock Option Level | AG1: Total Working Years | AH1: Work Life Balance | AI1: Years At Company | AJ1: Years In Current Role | AK1: Years Since Last Promotion | AL1: Years With Curr Manager
A2: Yes | B2: Travel_Rarely | C2: 35 - 44 | D2: Ex-Employees | E2: 0 | F2: Sales | G2: Life Sciences | H2: STAFF-1 | I2: 1 | J2: Female | K2: Sales Executive | L2: Single | M2: Yes | N2: Y | O2: 0 | P2: 41 | Q2: 1 | R2: Associates Degree | S2: 1 | T2: 2 | U2: 470 | V2: 40 | W2: 75200 | X2: #NAME? | Y2: 3 | Z2: 2 | AA2: 4 | AB2: 8 | AC2: 11 | AD2: 3 | AE2: 1 | AF2: 0 | AG2: 8 | AH2: 1 | AI2: 6 | AJ2: 4 | AK2: 0 | AL2: 5
A3: No | B3: Travel_Frequently | C3: 45 - 54 | D3: Current Employees | E3: 1 | F3: R&D | G3: Life Sciences | H3: STAFF-2 | I3: 2 | J3: Male | K3: Research Scientist | L3: Married | M3: No | N3: Y | O3: 3 | P3: 49 | Q3: 8 | R3: High School | S3: 1 | T3: 3 | U3: 305 | V3: 40 | W3: 48800 | X3: #NAME? | Y3: 2 | Z3: 2 | AA3: 2 | AB3: 1 | AC3: 23 | AD3: 4 | AE3: 4 | AF3: 1 | AG3: 10 | AH3: 3 | AI3: 10 | AJ3: 7 | AK3: 1 | AL3: 7
A4: Yes | B4: Travel_Rarely | C4: 35 - 44 | D4: Ex-Employees | E4: 0 | F4: R&D | G4: Other | H4: STAFF-3 | I4: 4 | J4: Male | K4: Laboratory Technician | L4: Single | M4: Yes | N4: Y | O4: 3 | P4: 37 | Q4: 2 | R4: Associates Degree | S4: 1 | T4: 4 | U4: 460 | V4: 40 | W4: 73600 | X4: #NAME? | Y4: 2 | Z4: 1 | AA4: 3 | AB4: 6 | AC4: 15 | AD4: 3 | AE4: 2 | AF4: 0 | AG4: 7 | AH4: 3 | AI4: 0 | AJ4: 0 | AK4: 0 | AL4: 0
A5: No | B5: Travel_Frequently | C5: 25 - 34 | D5: Current Employees | E5: 1 | F5: R&D | G5: Life Sciences | H5: STAFF-4 | I5: 5 | J5: Female | K5: Research Scientist | L5: Married | M5: Yes | N5: Y | O5: 3 | P5: 33 | Q5: 3 | R5: Master's Degree | S5: 1 | T5: 4 | U5: 280 | V5: 40 | W5: 44800 | X5: #NAME? | Y5: 3 | Z5: 1 | AA5: 3 | AB5: 1 | AC5: 11 | AD5: 3 | AE5: 3 | AF5: 0 | AG5: 8 | AH5: 3 | AI5: 8 | AJ5: 7 | AK5: 3 | AL5: 0
A6: No | B6: Travel_Rarely | C6: 25 - 34 | D6: Current Employees | E6: 1 | F6: R&D | G6: Medical | H6: STAFF-5 | I6: 7 | J6: Male | K6: Laboratory Technician | L6: Married | M6: No | N6: Y | O6: 3 | P6: 27 | Q6: 2 | R6: High School | S6: 1 | T6: 1 | U6: 200 | V6: 40 | W6: 32000 | X6: #NAME? | Y6: 3 | Z6: 1 | AA6: 2 | AB6: 9 | AC6: 12 | AD6: 3 | AE6: 4 | AF6: 1 | AG6: 6 | AH6: 3 | AI6: 2 | AJ6: 2 | AK6: 2 | AL6: 2
A7: No | B7: Travel_Frequently | C7: 25 - 34 | D7: Current Employees | E7: 1 | F7: R&D | G7: Life Sciences | H7: STAFF-6 | I7: 8 | J7: Male | K7: Laboratory Technician | L7: Single | M7: No | N7: Y | O7: 2 | P7: 32 | Q7: 2 | R7: Associates Degree | S7: 1 | T7: 4 | U7: 395 | V7: 40 | W7: 63200 | X7: #NAME? | Y7: 3 | Z7: 1 | AA7: 4 | AB7: 0 | AC7: 13 | AD7: 3 | AE7: 3 | AF7: 0 | AG7: 8 | AH7: 2 | AI7: 7 | AJ7: 7 | AK7: 3 | AL7: 6
A8: No | B8: Travel_Rarely | C8: Over 55 | D8: Current Employees | E8: 1 | F8: R&D | G8: Medical | H8: STAFF-7 | I8: 10 | J8: Female | K8: Laboratory Technician | L8: Married | M8: Yes | N8: Y | O8: 3 | P8: 59 | Q8: 3 | R8: Bachelor's Degree | S8: 1 | T8: 3 | U8: 405 | V8: 40 | W8: 64800 | X8: #NAME? | Y8: 4 | Z8: 1 | AA8: 1 | AB8: 4 | AC8: 20 | AD8: 4 | AE8: 1 | AF8: 3 | AG8: 12 | AH8: 2 | AI8: 1 | AJ8: 0 | AK8: 0 | AL8: 0
A9: No | B9: Travel_Rarely | C9: 25 - 34 | D9: Current Employees | E9: 1 | F9: R&D | G9: Life Sciences | H9: STAFF-8 | I9: 11 | J9: Male | K9: Laboratory Technician | L9: Divorced | M9: No | N9: Y | O9: 2 | P9: 30 | Q9: 24 | R9: High School | S9: 1 | T9: 4 | U9: 335 | V9: 40 | W9: 53600 | X9: #NAME? | Y9: 3 | Z9: 1 | AA9: 3 | AB9: 1 | AC9: 22 | AD9: 4 | AE9: 2 | AF9: 1 | AG9: 1 | AH9: 3 | AI9: 1 | AJ9: 0 | AK9: 0 | AL9: 0
A10: No | B10: Travel_Frequently | C10: 35 - 44 | D10: Current Employees | E10: 1 | F10: R&D | G10: Life Sciences | H10: STAFF-9 | I10: 12 | J10: Male | K10: Manufacturing Director | L10: Single | M10: No | N10: Y | O10: 2 | P10: 38 | Q10: 23 | R10: Bachelor's Degree | S10: 1 | T10: 4 | U10: 220 | V10: 40 | W10: 35200 | X10: #NAME? | Y10: 2 | Z10: 3 | AA10: 3 | AB10: 0 | AC10: 21 | AD10: 4 | AE10: 2 | AF10: 0 | AG10: 10 | AH10: 3 | AI10: 9 | AJ10: 7 | AK10: 1 | AL10: 8
A11: No | B11: Travel_Rarely | C11: 35 - 44 | D11: Current Employees | E11: 1 | F11: R&D | G11: Medical | H11: STAFF-10 | I11: 13 | J11: Male | K11: Healthcare Representative | L11: Married | M11: No | N11: Y | O11: 3 | P11: 36 | Q11: 27 | R11: Bachelor's Degree | S11: 1 | T11: 3 | U11: 470 | V11: 40 | W11: 75200 | X11: #NAME? | Y11: 3 | Z11: 2 | AA11: 3 | AB11: 6 | AC11: 13 | AD11: 3 | AE11: 2 | AF11: 2 | AG11: 17 | AH11: 2 | AI11: 7 | AJ11: 7 | AK11: 7 | AL11: 7
A12: No | B12: Travel_Rarely | C12: 35 - 44 | D12: Current Employees | E12: 1 | F12: R&D | G12: Medical | H12: STAFF-11 | I12: 14 | J12: Male | K12: Laboratory Technician | L12: Married | M12: No | N12: Y | O12: 5 | P12: 35 | Q12: 16 | R12: Bachelor's Degree | S12: 1 | T12: 1 | U12: 420 | V12: 40 | W12: 67200 | X12: #NAME? | Y12: 4 | Z12: 1 | AA12: 2 | AB12: 0 | AC12: 13 | AD12: 3 | AE12: 3 | AF12: 1 | AG12: 6 | AH12: 3 | AI12: 5 | AJ12: 4 | AK12: 0 | AL12: 3
A13: No | B13: Travel_Rarely | C13: 25 - 34 | D13: Current Employees | E13: 1 | F13: R&D | G13: Life Sciences | H13: STAFF-12 | I13: 15 | J13: Female | K13: Laboratory Technician | L13: Single | M13: Yes | N13: Y | O13: 3 | P13: 29 | Q13: 15 | R13: Associates Degree | S13: 1 | T13: 4 | U13: 245 | V13: 40 | W13: 39200 | X13: #NAME? | Y13: 2 | Z13: 2 | AA13: 3 | AB13: 0 | AC13: 12 | AD13: 3 | AE13: 4 | AF13: 0 | AG13: 10 | AH13: 3 | AI13: 9 | AJ13: 5 | AK13: 0 | AL13: 8
... A1469: Yes | B1469: Travel_Frequently | C1469: 35 - 44 | D1469: Ex-Employees | E1469: 0 | F1469: Sales | G1469: Other | H1469: STAFF-1468 | I1469: 1667 | J1469: Male | K1469: Sales Executive | L1469: Single | M1469: Yes | N1469: Y | O1469: 2 | P1469: 35 | Q1469: 12 | R1469: Master's Degree | S1469: 1 | T1469: 4 | U1469: 180 | V1469: 40 | W1469: 28800 | X1469: #NAME? | Y1469: 3 | Z1469: 2 | AA1469: 4 | AB1469: 3 | AC1469: 24 | AD1469: 4 | AE1469: 1 | AF1469: 0 | AG1469: 13 | AH1469: 4 | AI1469: 11 | AJ1469: 9 | AK1469: 6 | AL1469: 7
A1470: Yes | B1470: Travel_Rarely | C1470: Under 25 | D1470: Ex-Employees | E1470: 0 | F1470: R&D | G1470: Life Sciences | H1470: STAFF-1469 | J1470: Male | K1470: Research Scientist | L1470: Single | M1470: Yes | N1470: Y | O1470: 2 | P1470: 22 | Q1470: 7 | R1470: High School | S1470: 1 | T1470: 4 | U1470: 375 | V1470: 40 | W1470: 60000 | X1470: #NAME? | Y1470: 3 | Z1470: 1 | AA1470: 2 | AB1470: 1 | AC1470: 23 | AD1470: 4 | AE1470: 1 | AF1470: 0 | AG1470: 1 | AH1470: 3 | AI1470: 1 | AJ1470: 0 | AK1470: 0 | AL1470: 0
A1471: Yes | B1471: Travel_Rarely | C1471: Under 25 | D1471: Ex-Employees | E1471: 0 | F1471: Sales | G1471: Life Sciences | H1471: STAFF-1470 | I1471: 1878 | J1471: Male | K1471: Sales Representative | L1471: Divorced | M1471: Yes | N1471: Y | O1471: 2 | P1471: 23 | Q1471: 7 | R1471: Bachelor's Degree | S1471: 1 | T1471: 3 | U1471: 495 | V1471: 40 | W1471: 79200 | X1471: #NAME? | Y1471: 3 | Z1471: 1 | AA1471: 4 | AB1471: 1 | AC1471: 21 | AD1471: 4 | AE1471: 2 | AF1471: 1 | AG1471: 3 | AH1471: 3 | AI1471: 3 | AJ1471: 2 | AK1471: 0 | AL1471: 2
A1472: No | B1472: Non-Travel | C1472: Under 25 | D1472: Current Employees | E1472: 1 | F1472: R&D | G1472: Medical | H1472: STAFF-1471 | I1472: 1879 | J1472: Male | K1472: Laboratory Technician | L1472: Divorced | M1472: Yes | N1472: Y | O1472: 2 | P1472: 22 | Q1472: 16 | R1472: Associates Degree | S1472: 1 | T1472: 4 | U1472: 480 | V1472: 40 | W1472: 76800 | X1472: #NAME? | Y1472: 4 | Z1472: 1 | AA1472: 4 | AB1472: 1 | AC1472: 13 | AD1472: 3 | AE1472: 2 | AF1472: 2 | AG1472: 1 | AH1472: 2 | AI1472: 1 | AJ1472: 0 | AK1472: 0 | AL1472: 0
A1473: No | B1473: Travel_Rarely | C1473: 45 - 54 | D1473: Current Employees | E1473: 1 | F1473: Sales | G1473: Life Sciences | H1473: STAFF-1472 | I1473: 1880 | J1473: Female | K1473: Manager | L1473: Married | M1473: No | N1473: Y | O1473: 3 | P1473: 53 | Q1473: 2 | R1473: Master's Degree | S1473: 1 | T1473: 1 | U1473: 390 | V1473: 40 | W1473: 62400 | X1473: #NAME? | Y1473: 2 | Z1473: 4 | AA1473: 4 | AB1473: 2 | AC1473: 16 | AD1473: 3 | AE1473: 3 | AF1473: 0 | AG1473: 31 | AH1473: 3 | AI1473: 25 | AJ1473: 8 | AK1473: 3 | AL1473: 7
A1474: No | B1474: Travel_Rarely | C1474: 35 - 44 | D1474: Current Employees | E1474: 1 | F1474: R&D | G1474: Life Sciences | H1474: STAFF-1473 | I1474: 1881 | J1474: Male | K1474: Research Scientist | L1474: Single | M1474: Yes | N1474: Y | O1474: 3 | P1474: 38 | Q1474: 2 | R1474: Bachelor's Degree | S1474: 1 | T1474: 4 | U1474: 225 | V1474: 40 | W1474: 36000 | X1474: #NAME? | Y1474: 3 | Z1474: 1 | AA1474: 4 | AB1474: 5 | AC1474: 11 | AD1474: 3 | AE1474: 3 | AF1474: 0 | AG1474: 6 | AH1474: 3 | AI1474: 3 | AJ1474: 2 | AK1474: 1 | AL1474: 2
A1475: No | B1475: Non-Travel | C1475: Under 25 | D1475: Current Employees | E1475: 1 | F1475: R&D | G1475: Other | H1475: STAFF-1474 | I1475: 1882 | J1475: Female | K1475: Manufacturing Director | L1475: Divorced | M1475: No | N1475: Y | O1475: 5 | P1475: 24 | Q1475: 11 | R1475: Associates Degree | S1475: 1 | T1475: 1 | U1475: 480 | V1475: 40 | W1475: 76800 | X1475: #NAME? | Y1475: 4 | Z1475: 2 | AA1475: 3 | AB1475: 0 | AC1475: 18 | AD1475: 3 | AE1475: 4 | AF1475: 1 | AG1475: 5 | AH1475: 2 | AI1475: 4 | AJ1475: 2 | AK1475: 1 | AL1475: 3
A1476: Yes | B1476: Travel_Rarely | C1476: 35 - 44 | D1476: Ex-Employees | E1476: 0 | F1476: Sales | G1476: Life Sciences | H1476: STAFF-1475 | I1476: 1883 | J1476: Male | K1476: Sales Representative | L1476: Single | M1476: No | N1476: Y | O1476: 4 | P1476: 36 | Q1476: 9 | R1476: Master's Degree | S1476: 1 | T1476: 3 | U1476: 410 | V1476: 40 | W1476: 65600 | X1476: #NAME? | Y1476: 2 | Z1476: 1 | AA1476: 1 | AB1476: 7 | AC1476: 23 | AD1476: 4 | AE1476: 2 | AF1476: 0 | AG1476: 10 | AH1476: 3 | AI1476: 5 | AJ1476: 3 | AK1476: 0 | AL1476: 3
A1477: No | B1477: Travel_Rarely | C1477: 25 - 34 | D1477: Current Employees | E1477: 1 | F1477: R&D | G1477: Life Sciences | H1477: STAFF-1476 | I1477: 1884 | J1477: Female | K1477: Research Director | L1477: Single | M1477: No | N1477: Y | O1477: 4 | P1477: 34 | Q1477: 7 | R1477: Master's Degree | S1477: 1 | T1477: 1 | U1477: 265 | V1477: 40 | W1477: 42400 | X1477: #NAME? | Y1477: 3 | Z1477: 3 | AA1477: 2 | AB1477: 0 | AC1477: 11 | AD1477: 3 | AE1477: 3 | AF1477: 0 | AG1477: 13 | AH1477: 3 | AI1477: 12 | AJ1477: 6 | AK1477: 2 | AL1477: 11
A1478: No | B1478: Travel_Rarely | C1478: Under 25 | D1478: Current Employees | E1478: 1 | F1478: R&D | G1478: Life Sciences | H1478: STAFF-1477 | I1478: 1885 | J1478: Male | K1478: Research Scientist | L1478: Single | M1478: No | N1478: Y | O1478: 6 | P1478: 21 | Q1478: 15 | R1478: Associates Degree | S1478: 1 | T1478: 3 | U1478: 480 | V1478: 40 | W1478: 76800 | X1478: #NAME? | Y1478: 3 | Z1478: 1 | AA1478: 4 | AB1478: 1 | AC1478: 14 | AD1478: 3 | AE1478: 4 | AF1478: 0 | AG1478: 0 | AH1478: 3 | AI1478: 0 | AJ1478: 0 | AK1478: 0 | AL1478: 0
A1479: Yes | B1479: Travel_Rarely | C1479: 25 - 34 | D1479: Ex-Employees | E1479: 0 | F1479: R&D | G1479: Medical | H1479: STAFF-1478 | I1479: 1886 | J1479: Male | K1479: Research Scientist | L1479: Single | M1479: No | N1479: Y | O1479: 2 | P1479: 34 | Q1479: 6 | R1479: High School | S1479: 1 | T1479: 2 | U1479: 415 | V1479: 40 | W1479: 66400 | X1479: #NAME? | Y1479: 3 | Z1479: 1 | AA1479: 1 | AB1479: 2 | AC1479: 11 | AD1479: 3 | AE1479: 3 | AF1479: 0 | AG1479: 8 | AH1479: 3 | AI1479: 4 | AJ1479: 2 | AK1479: 1 | AL1479: 3
A1480: No | B1480: Travel_Rarely | C1480: 45 - 54 | D1480: Current Employees | E1480: 1 | F1480: R&D | G1480: Other | H1480: STAFF-1479 | I1480: 1887 | J1480: Female | K1480: Manager | L1480: Divorced | M1480: No | N1480: Y | O1480: 3 | P1480: 53 | Q1480: 5 | R1480: Bachelor's Degree | S1480: 1 | T1480: 3 | U1480: 290 | V1480: 40 | W1480: 46400 | X1480: #NAME? | Y1480: 3 | Z1480: 5 | AA1480: 3 | AB1480: 4 | AC1480: 11 | AD1480: 3 | AE1480: 4 | AF1480: 1 | AG1480: 26 | AH1480: 2 | AI1480: 14 | AJ1480: 13 | AK1480: 4 | AL1480: 8
A1481: Yes | B1481: Travel_Frequently | C1481: 25 - 34 | D1481: Ex-Employees | E1481: 0 | F1481: R&D | G1481: Life Sciences | H1481: STAFF-1480 | I1481: 1888 | J1481: Female | K1481: Research Scientist | L1481: Single | M1481: Yes | N1481: Y | O1481: 5 | P1481: 32 | Q1481: 16 | R1481: High School | S1481: 1 | T1481: 2 | U1481: 360 | V1481: 40 | W1481: 57600 | X1481: #NAME? | Y1481: 1 | Z1481: 1 | AA1481: 1 | AB1481: 1 | AC1481: 22 | AD1481: 4 | AE1481: 2 | AF1481: 0 | AG1481: 10 | AH1481: 3 | AI1481: 10 | AJ1481: 2 | AK1481: 6 | AL1481: 7
A1482: No | B1482: Travel_Rarely | C1482: 35 - 44 | D1482: Current Employees | E1482: 1 | F1482: Sales | G1482: Marketing | H1482: STAFF-1481 | I1482: 1889 | J1482: Male | K1482: Sales Executive | L1482: Married | M1482: No | N1482: Y | O1482: 2 | P1482: 42 | Q1482: 8 | R1482: Master's Degree | S1482: 1 | T1482: 3 | U1482: 240 | V1482: 40 | W1482: 38400 | X1482: #NAME? | Y1482: 3 | Z1482: 2 | AA1482: 2 | AB1482: 0 | AC1482: 11 | AD1482: 3 | AE1482: 4 | AF1482: 1 | AG1482: 10 | AH1482: 3 | AI1482: 9 | AJ1482: 7 | AK1482: 4 | AL1482: 2
... A2926: Yes | B2926: Travel_Rarely | C2926: Under 27 | D2926: Ex-Employees | E2926: 0 | F2926: Sales | G2926: Life Sciences | H2926: STAFF-2925 | I2926: 3333 | J2926: Male | K2926: Sales Representative | L2926: Divorced | M2926: Yes | N2926: Y | O2926: 2 | P2926: 23 | Q2926: 7 | R2926: Bachelor's Degree | S2926: 1 | T2926: 3 | U2926: 495 | V2926: 40 | W2926: 79200 | X2926: #NAME? | Y2926: 3 | Z2926: 1 | AA2926: 4 | AB2926: 1 | AC2926: 21 | AD2926: 4 | AE2926: 2 | AF2926: 1 | AG2926: 3 | AH2926: 3 | AI2926: 3 | AJ2926: 2 | AK2926: 0 | AL2926: 2

Sheet Clean Data
A1: =IF('Raw DataSet'!I1="","Unknown",'Raw DataSet'!I1) -> Employee Number | B1: =IF('Raw DataSet'!H1="", "Unknown", 'Raw DataSet'!H1) -> emp no | C1: =IF('Raw DataSet'!J1="","Unknow",'Raw DataSet'!J1) -> Gender | D1: =IF('Raw DataSet'!G1="","Unknown",'Raw DataSet'!G1) -> Education Field | E1: =IF('Raw DataSet'!R1="","Unknown",'Raw DataSet'!R1) -> Education | F1: =IF('Raw DataSet'!L1="","Unknown",'Raw DataSet'!L1) -> Marital Status | G1: =IF('Raw DataSet'!P1="","Unknown",'Raw DataSet'!P1) -> Age | H1: Age Group | I1: =IF('Raw DataSet'!F1="","Unknown",'Raw DataSet'!F1) -> Department | J1: =IF('Raw DataSet'!K1="","Unknown",'Raw DataSet'!K1) -> Job Role | K1: =IF('Raw DataSet'!Q1="","Unknown",'Raw DataSet'!Q1) -> Distance From Home | L1: Distance Group | M1: Attrition | N1: Attrition Num | O1: =IF('Raw DataSet'!W1="","Unknown",'Raw DataSet'!W1) -> Monthly Income | P1: Income Group | Q1: =IF('Raw DataSet'!M1="","Unknown",'Raw DataSet'!M1) -> Over Time | R1: =IF('Raw DataSet'!T1="","Unknown",'Raw DataSet'!T1) -> Environment Satisfaction | S1: =IF('Raw DataSet'!Y1="","Unknown",'Raw DataSet'!Y1) -> Job Involvement | T1: =IF('Raw DataSet'!Z1="","Unknown",'Raw DataSet'!Z1) -> Job Level | U1: =IF('Raw DataSet'!AA1="","Unknown",'Raw DataSet'!AA1) -> Job Satisfaction | V1: =IF('Raw DataSet'!AB1="","Unknown",'Raw DataSet'!AB1) -> Num Companies Worked | W1: =IF('Raw DataSet'!AC1="","Unknown",'Raw DataSet'!AC1) -> Percent Salary Hike | X1: Salary Hike Group | Y1: =IF('Raw DataSet'!AD1="","Unknown",'Raw DataSet'!AD1) -> Performance Rating | Z1: =IF('Raw DataSet'!AE1="","Unknown",'Raw DataSet'!AE1) -> Relationship Satisfaction | AA1: =IF('Raw DataSet'!AF1="","Unknown",'Raw DataSet'!AF1) -> Stock Option Level | AB1: =IF('Raw DataSet'!AG1="","Unknown",'Raw DataSet'!AG1) -> Total Working Years | AC1: =IF('Raw DataSet'!AH1="","Unknown",'Raw DataSet'!AH1) -> Work Life Balance | AD1: =IF('Raw DataSet'!AI1="","Unknown",'Raw DataSet'!AI1) -> Years At Company | AE1: =IF('Raw DataSet'!AJ1="","Unknown",'Raw DataSet'!AJ1) -> Years In Current Role | AF1: =IF('Raw DataSet'!AK1="","Unknown",'Raw DataSet'!AK1) -> Years Since Last Promotion | AG1: =IF('Raw DataSet'!AL1="","Unknown",'Raw DataSet'!AL1) -> Years With Curr Manager
A2: =IF('Raw DataSet'!I2="","Unknown",'Raw DataSet'!I2) -> 1 | B2: =IF('Raw DataSet'!H2="", "Unknown", 'Raw DataSet'!H2) -> STAFF-1 | C2: =IF('Raw DataSet'!J2="","Unknow",'Raw DataSet'!J2) -> Female | D2: =IF('Raw DataSet'!G2="","Unknown",'Raw DataSet'!G2) -> Life Sciences | E2: =IF('Raw DataSet'!R2="","Unknown",'Raw DataSet'!R2) -> Associates Degree | F2: =IF('Raw DataSet'!L2="","Unknown",'Raw DataSet'!L2) -> Single | G2: =IF('Raw DataSet'!P2="","Unknown",'Raw DataSet'!P2) -> 41 | H2: {=_xlfn.IFS(G2<24, "Under 25",G2<35, "25-34",G2<45, "35-44",G2<55, "45-54",TRUE, "Over 55")} -> 35-44 | I2: =IF('Raw DataSet'!F2="","Unknown",'Raw DataSet'!F2) -> Sales | J2: =IF('Raw DataSet'!K2="","Unknown",'Raw DataSet'!K2) -> Sales Executive | K2: =IF('Raw DataSet'!Q2="","Unknown",'Raw DataSet'!Q2) -> 1 | L2: {=_xlfn.IFS(K2<10,"0-9",K2<20,"10-19",TRUE,"20+")} -> 0-9 | M2: ='Raw DataSet'!A2 -> Yes | N2: =IF(M2="Yes",1,0) -> 1 | O2: =IF('Raw DataSet'!W2="","Unknown",'Raw DataSet'!W2) -> 75200 | P2: =IF(O2 <= QUARTILE($O:$O, 1), "Low", IF(O2 <= QUARTILE($O:$O, 3), "Medium", "High")) -> High | Q2: =IF('Raw DataSet'!M2="","Unknown",'Raw DataSet'!M2) -> Yes | R2: =IF('Raw DataSet'!T2="","Unknown",'Raw DataSet'!T2) -> 2 | S2: =IF('Raw DataSet'!Y2="","Unknown",'Raw DataSet'!Y2) -> 3 | T2: =IF('Raw DataSet'!Z2="","Unknown",'Raw DataSet'!Z2) -> 2 | U2: =IF('Raw DataSet'!AA2="","Unknown",'Raw DataSet'!AA2) -> 4 | V2: =IF('Raw DataSet'!AB2="","Unknown",'Raw DataSet'!AB2) -> 8 | W2: =IF('Raw DataSet'!AC2="","Unknown",'Raw DataSet'!AC2) -> 11 | X2: {=_xlfn.IFS(W2<15,"Under 15", W2<20,"15-19", TRUE,"Over 20")} -> Under 15 | Y2: =IF('Raw DataSet'!AD2="","Unknown",'Raw DataSet'!AD2) -> 3 | Z2: =IF('Raw DataSet'!AE2="","Unknown",'Raw DataSet'!AE2) -> 1 | AA2: =IF('Raw DataSet'!AF2="","Unknown",'Raw DataSet'!AF2) -> 0 | AB2: =IF('Raw DataSet'!AG2="","Unknown",'Raw DataSet'!AG2) -> 8 | AC2: =IF('Raw DataSet'!AH2="","Unknown",'Raw DataSet'!AH2) -> 1 | AD2: =IF('Raw DataSet'!AI2="","Unknown",'Raw DataSet'!AI2) -> 6 | AE2: =IF('Raw DataSet'!AJ2="","Unknown",'Raw DataSet'!AJ2) -> 4 | AF2: =IF('Raw DataSet'!AK2="","Unknown",'Raw DataSet'!AK2) -> 0 | AG2: =IF('Raw DataSet'!AL2="","Unknown",'Raw DataSet'!AL2) -> 5
A3: =IF('Raw DataSet'!I3="","Unknown",'Raw DataSet'!I3) -> 2 | B3: =IF('Raw DataSet'!H3="", "Unknown", 'Raw DataSet'!H3) -> STAFF-2 | C3: =IF('Raw DataSet'!J3="","Unknow",'Raw DataSet'!J3) -> Male | D3: =IF('Raw DataSet'!G3="","Unknown",'Raw DataSet'!G3) -> Life Sciences | E3: =IF('Raw DataSet'!R3="","Unknown",'Raw DataSet'!R3) -> High School | F3: =IF('Raw DataSet'!L3="","Unknown",'Raw DataSet'!L3) -> Married | G3: =IF('Raw DataSet'!P3="","Unknown",'Raw DataSet'!P3) -> 49 | H3: {=_xlfn.IFS(G3<24, "Under 25",G3<35, "25-34",G3<45, "35-44",G3<55, "45-54",TRUE, "Over 55")} -> 45-54 | I3: =IF('Raw DataSet'!F3="","Unknown",'Raw DataSet'!F3) -> R&D | J3: =IF('Raw DataSet'!K3="","Unknown",'Raw DataSet'!K3) -> Research Scientist | K3: =IF('Raw DataSet'!Q3="","Unknown",'Raw DataSet'!Q3) -> 8 | L3: {=_xlfn.IFS(K3<10,"0-9",K3<20,"10-19",TRUE,"20+")} -> 0-9 | M3: ='Raw DataSet'!A3 -> No | N3: =IF(M3="Yes",1,0) -> 0 | O3: =IF('Raw DataSet'!W3="","Unknown",'Raw DataSet'!W3) -> 48800 | P3: =IF(O3 <= QUARTILE($O:$O, 1), "Low", IF(O3 <= QUARTILE($O:$O, 3), "Medium", "High")) -> Medium | Q3: =IF('Raw DataSet'!M3="","Unknown",'Raw DataSet'!M3) -> No | R3: =IF('Raw DataSet'!T3="","Unknown",'Raw DataSet'!T3) -> 3 | S3: =IF('Raw DataSet'!Y3="","Unknown",'Raw DataSet'!Y3) -> 2 | T3: =IF('Raw DataSet'!Z3="","Unknown",'Raw DataSet'!Z3) -> 2 | U3: =IF('Raw DataSet'!AA3="","Unknown",'Raw DataSet'!AA3) -> 2 | V3: =IF('Raw DataSet'!AB3="","Unknown",'Raw DataSet'!AB3) -> 1 | W3: =IF('Raw DataSet'!AC3="","Unknown",'Raw DataSet'!AC3) -> 23 | X3: {=_xlfn.IFS(W3<15,"Under 15", W3<20,"15-19", TRUE,"Over 20")} -> Over 20 | Y3: =IF('Raw DataSet'!AD3="","Unknown",'Raw DataSet'!AD3) -> 4 | Z3: =IF('Raw DataSet'!AE3="","Unknown",'Raw DataSet'!AE3) -> 4 | AA3: =IF('Raw DataSet'!AF3="","Unknown",'Raw DataSet'!AF3) -> 1 | AB3: =IF('Raw DataSet'!AG3="","Unknown",'Raw DataSet'!AG3) -> 10 | AC3: =IF('Raw DataSet'!AH3="","Unknown",'Raw DataSet'!AH3) -> 3 | AD3: =IF('Raw DataSet'!AI3="","Unknown",'Raw DataSet'!AI3) -> 10 | AE3: =IF('Raw DataSet'!AJ3="","Unknown",'Raw DataSet'!AJ3) -> 7 | AF3: =IF('Raw DataSet'!AK3="","Unknown",'Raw DataSet'!AK3) -> 1 | AG3: =IF('Raw DataSet'!AL3="","Unknown",'Raw DataSet'!AL3) -> 7
A4: =IF('Raw DataSet'!I4="","Unknown",'Raw DataSet'!I4) -> 4 | B4: =IF('Raw DataSet'!H4="", "Unknown", 'Raw DataSet'!H4) -> STAFF-3 | C4: =IF('Raw DataSet'!J4="","Unknow",'Raw DataSet'!J4) -> Male | D4: =IF('Raw DataSet'!G4="","Unknown",'Raw DataSet'!G4) -> Other | E4: =IF('Raw DataSet'!R4="","Unknown",'Raw DataSet'!R4) -> Associates Degree | F4: =IF('Raw DataSet'!L4="","Unknown",'Raw DataSet'!L4) -> Single | G4: =IF('Raw DataSet'!P4="","Unknown",'Raw DataSet'!P4) -> 37 | H4: {=_xlfn.IFS(G4<24, "Under 25",G4<35, "25-34",G4<45, "35-44",G4<55, "45-54",TRUE, "Over 55")} -> 35-44 | I4: =IF('Raw DataSet'!F4="","Unknown",'Raw DataSet'!F4) -> R&D | J4: =IF('Raw DataSet'!K4="","Unknown",'Raw DataSet'!K4) -> Laboratory Technician | K4: =IF('Raw DataSet'!Q4="","Unknown",'Raw DataSet'!Q4) -> 2 | L4: {=_xlfn.IFS(K4<10,"0-9",K4<20,"10-19",TRUE,"20+")} -> 0-9 | M4: ='Raw DataSet'!A4 -> Yes | N4: =IF(M4="Yes",1,0) -> 1 | O4: =IF('Raw DataSet'!W4="","Unknown",'Raw DataSet'!W4) -> 73600 | P4: =IF(O4 <= QUARTILE($O:$O, 1), "Low", IF(O4 <= QUARTILE($O:$O, 3), "Medium", "High")) -> High | Q4: =IF('Raw DataSet'!M4="","Unknown",'Raw DataSet'!M4) -> Yes | R4: =IF('Raw DataSet'!T4="","Unknown",'Raw DataSet'!T4) -> 4 | S4: =IF('Raw DataSet'!Y4="","Unknown",'Raw DataSet'!Y4) -> 2 | T4: =IF('Raw DataSet'!Z4="","Unknown",'Raw DataSet'!Z4) -> 1 | U4: =IF('Raw DataSet'!AA4="","Unknown",'Raw DataSet'!AA4) -> 3 | V4: =IF('Raw DataSet'!AB4="","Unknown",'Raw DataSet'!AB4) -> 6 | W4: =IF('Raw DataSet'!AC4="","Unknown",'Raw DataSet'!AC4) -> 15 | X4: {=_xlfn.IFS(W4<15,"Under 15", W4<20,"15-19", TRUE,"Over 20")} -> 15-19 | Y4: =IF('Raw DataSet'!AD4="","Unknown",'Raw DataSet'!AD4) -> 3 | Z4: =IF('Raw DataSet'!AE4="","Unknown",'Raw DataSet'!AE4) -> 2 | AA4: =IF('Raw DataSet'!AF4="","Unknown",'Raw DataSet'!AF4) -> 0 | AB4: =IF('Raw DataSet'!AG4="","Unknown",'Raw DataSet'!AG4) -> 7 | AC4: =IF('Raw DataSet'!AH4="","Unknown",'Raw DataSet'!AH4) -> 3 | AD4: =IF('Raw DataSet'!AI4="","Unknown",'Raw DataSet'!AI4) -> 0 | AE4: =IF('Raw DataSet'!AJ4="","Unknown",'Raw DataSet'!AJ4) -> 0 | AF4: =IF('Raw DataSet'!AK4="","Unknown",'Raw DataSet'!AK4) -> 0 | AG4: =IF('Raw DataSet'!AL4="","Unknown",'Raw DataSet'!AL4) -> 0
A5: =IF('Raw DataSet'!I5="","Unknown",'Raw DataSet'!I5) -> 5 | B5: =IF('Raw DataSet'!H5="", "Unknown", 'Raw DataSet'!H5) -> STAFF-4 | C5: =IF('Raw DataSet'!J5="","Unknow",'Raw DataSet'!J5) -> Female | D5: =IF('Raw DataSet'!G5="","Unknown",'Raw DataSet'!G5) -> Life Sciences | E5: =IF('Raw DataSet'!R5="","Unknown",'Raw DataSet'!R5) -> Master's Degree | F5: =IF('Raw DataSet'!L5="","Unknown",'Raw DataSet'!L5) -> Married | G5: =IF('Raw DataSet'!P5="","Unknown",'Raw DataSet'!P5) -> 33 | H5: {=_xlfn.IFS(G5<24, "Under 25",G5<35, "25-34",G5<45, "35-44",G5<55, "45-54",TRUE, "Over 55")} -> 25-34 | I5: =IF('Raw DataSet'!F5="","Unknown",'Raw DataSet'!F5) -> R&D | J5: =IF('Raw DataSet'!K5="","Unknown",'Raw DataSet'!K5) -> Research Scientist | K5: =IF('Raw DataSet'!Q5="","Unknown",'Raw DataSet'!Q5) -> 3 | L5: {=_xlfn.IFS(K5<10,"0-9",K5<20,"10-19",TRUE,"20+")} -> 0-9 | M5: ='Raw DataSet'!A5 -> No | N5: =IF(M5="Yes",1,0) -> 0 | O5: =IF('Raw DataSet'!W5="","Unknown",'Raw DataSet'!W5) -> 44800 | P5: =IF(O5 <= QUARTILE($O:$O, 1), "Low", IF(O5 <= QUARTILE($O:$O, 3), "Medium", "High")) -> Medium | Q5: =IF('Raw DataSet'!M5="","Unknown",'Raw DataSet'!M5) -> Yes | R5: =IF('Raw DataSet'!T5="","Unknown",'Raw DataSet'!T5) -> 4 | S5: =IF('Raw DataSet'!Y5="","Unknown",'Raw DataSet'!Y5) -> 3 | T5: =IF('Raw DataSet'!Z5="","Unknown",'Raw DataSet'!Z5) -> 1 | U5: =IF('Raw DataSet'!AA5="","Unknown",'Raw DataSet'!AA5) -> 3 | V5: =IF('Raw DataSet'!AB5="","Unknown",'Raw DataSet'!AB5) -> 1 | W5: =IF('Raw DataSet'!AC5="","Unknown",'Raw DataSet'!AC5) -> 11 | X5: {=_xlfn.IFS(W5<15,"Under 15", W5<20,"15-19", TRUE,"Over 20")} -> Under 15 | Y5: =IF('Raw DataSet'!AD5="","Unknown",'Raw DataSet'!AD5) -> 3 | Z5: =IF('Raw DataSet'!AE5="","Unknown",'Raw DataSet'!AE5) -> 3 | AA5: =IF('Raw DataSet'!AF5="","Unknown",'Raw DataSet'!AF5) -> 0 | AB5: =IF('Raw DataSet'!AG5="","Unknown",'Raw DataSet'!AG5) -> 8 | AC5: =IF('Raw DataSet'!AH5="","Unknown",'Raw DataSet'!AH5) -> 3 | AD5: =IF('Raw DataSet'!AI5="","Unknown",'Raw DataSet'!AI5) -> 8 | AE5: =IF('Raw DataSet'!AJ5="","Unknown",'Raw DataSet'!AJ5) -> 7 | AF5: =IF('Raw DataSet'!AK5="","Unknown",'Raw DataSet'!AK5) -> 3 | AG5: =IF('Raw DataSet'!AL5="","Unknown",'Raw DataSet'!AL5) -> 0
A6: =IF('Raw DataSet'!I6="","Unknown",'Raw DataSet'!I6) -> 7 | B6: =IF('Raw DataSet'!H6="", "Unknown", 'Raw DataSet'!H6) -> STAFF-5 | C6: =IF('Raw DataSet'!J6="","Unknow",'Raw DataSet'!J6) -> Male | D6: =IF('Raw DataSet'!G6="","Unknown",'Raw DataSet'!G6) -> Medical | E6: =IF('Raw DataSet'!R6="","Unknown",'Raw DataSet'!R6) -> High School | F6: =IF('Raw DataSet'!L6="","Unknown",'Raw DataSet'!L6) -> Married | G6: =IF('Raw DataSet'!P6="","Unknown",'Raw DataSet'!P6) -> 27 | H6: {=_xlfn.IFS(G6<24, "Under 25",G6<35, "25-34",G6<45, "35-44",G6<55, "45-54",TRUE, "Over 55")} -> 25-34 | I6: =IF('Raw DataSet'!F6="","Unknown",'Raw DataSet'!F6) -> R&D | J6: =IF('Raw DataSet'!K6="","Unknown",'Raw DataSet'!K6) -> Laboratory Technician | K6: =IF('Raw DataSet'!Q6="","Unknown",'Raw DataSet'!Q6) -> 2 | L6: {=_xlfn.IFS(K6<10,"0-9",K6<20,"10-19",TRUE,"20+")} -> 0-9 | M6: ='Raw DataSet'!A6 -> No | N6: =IF(M6="Yes",1,0) -> 0 | O6: =IF('Raw DataSet'!W6="","Unknown",'Raw DataSet'!W6) -> 32000 | P6: =IF(O6 <= QUARTILE($O:$O, 1), "Low", IF(O6 <= QUARTILE($O:$O, 3), "Medium", "High")) -> Low | Q6: =IF('Raw DataSet'!M6="","Unknown",'Raw DataSet'!M6) -> No | R6: =IF('Raw DataSet'!T6="","Unknown",'Raw DataSet'!T6) -> 1 | S6: =IF('Raw DataSet'!Y6="","Unknown",'Raw DataSet'!Y6) -> 3 | T6: =IF('Raw DataSet'!Z6="","Unknown",'Raw DataSet'!Z6) -> 1 | U6: =IF('Raw DataSet'!AA6="","Unknown",'Raw DataSet'!AA6) -> 2 | V6: =IF('Raw DataSet'!AB6="","Unknown",'Raw DataSet'!AB6) -> 9 | W6: =IF('Raw DataSet'!AC6="","Unknown",'Raw DataSet'!AC6) -> 12 | X6: {=_xlfn.IFS(W6<15,"Under 15", W6<20,"15-19", TRUE,"Over 20")} -> Under 15 | Y6: =IF('Raw DataSet'!AD6="","Unknown",'Raw DataSet'!AD6) -> 3 | Z6: =IF('Raw DataSet'!AE6="","Unknown",'Raw DataSet'!AE6) -> 4 | AA6: =IF('Raw DataSet'!AF6="","Unknown",'Raw DataSet'!AF6) -> 1 | AB6: =IF('Raw DataSet'!AG6="","Unknown",'Raw DataSet'!AG6) -> 6 | AC6: =IF('Raw DataSet'!AH6="","Unknown",'Raw DataSet'!AH6) -> 3 | AD6: =IF('Raw DataSet'!AI6="","Unknown",'Raw DataSet'!AI6) -> 2 | AE6: =IF('Raw DataSet'!AJ6="","Unknown",'Raw DataSet'!AJ6) -> 2 | AF6: =IF('Raw DataSet'!AK6="","Unknown",'Raw DataSet'!AK6) -> 2 | AG6: =IF('Raw DataSet'!AL6="","Unknown",'Raw DataSet'!AL6) -> 2
A7: =IF('Raw DataSet'!I7="","Unknown",'Raw DataSet'!I7) -> 8 | B7: =IF('Raw DataSet'!H7="", "Unknown", 'Raw DataSet'!H7) -> STAFF-6 | C7: =IF('Raw DataSet'!J7="","Unknow",'Raw DataSet'!J7) -> Male | D7: =IF('Raw DataSet'!G7="","Unknown",'Raw DataSet'!G7) -> Life Sciences | E7: =IF('Raw DataSet'!R7="","Unknown",'Raw DataSet'!R7) -> Associates Degree | F7: =IF('Raw DataSet'!L7="","Unknown",'Raw DataSet'!L7) -> Single | G7: =IF('Raw DataSet'!P7="","Unknown",'Raw DataSet'!P7) -> 32 | H7: {=_xlfn.IFS(G7<24, "Under 25",G7<35, "25-34",G7<45, "35-44",G7<55, "45-54",TRUE, "Over 55")} -> 25-34 | I7: =IF('Raw DataSet'!F7="","Unknown",'Raw DataSet'!F7) -> R&D | J7: =IF('Raw DataSet'!K7="","Unknown",'Raw DataSet'!K7) -> Laboratory Technician | K7: =IF('Raw DataSet'!Q7="","Unknown",'Raw DataSet'!Q7) -> 2 | L7: {=_xlfn.IFS(K7<10,"0-9",K7<20,"10-19",TRUE,"20+")} -> 0-9 | M7: ='Raw DataSet'!A7 -> No | N7: =IF(M7="Yes",1,0) -> 0 | O7: =IF('Raw DataSet'!W7="","Unknown",'Raw DataSet'!W7) -> 63200 | P7: =IF(O7 <= QUARTILE($O:$O, 1), "Low", IF(O7 <= QUARTILE($O:$O, 3), "Medium", "High")) -> Medium | Q7: =IF('Raw DataSet'!M7="","Unknown",'Raw DataSet'!M7) -> No | R7: =IF('Raw DataSet'!T7="","Unknown",'Raw DataSet'!T7) -> 4 | S7: =IF('Raw DataSet'!Y7="","Unknown",'Raw DataSet'!Y7) -> 3 | T7: =IF('Raw DataSet'!Z7="","Unknown",'Raw DataSet'!Z7) -> 1 | U7: =IF('Raw DataSet'!AA7="","Unknown",'Raw DataSet'!AA7) -> 4 | V7: =IF('Raw DataSet'!AB7="","Unknown",'Raw DataSet'!AB7) -> 0 | W7: =IF('Raw DataSet'!AC7="","Unknown",'Raw DataSet'!AC7) -> 13 | X7: {=_xlfn.IFS(W7<15,"Under 15", W7<20,"15-19", TRUE,"Over 20")} -> Under 15 | Y7: =IF('Raw DataSet'!AD7="","Unknown",'Raw DataSet'!AD7) -> 3 | Z7: =IF('Raw DataSet'!AE7="","Unknown",'Raw DataSet'!AE7) -> 3 | AA7: =IF('Raw DataSet'!AF7="","Unknown",'Raw DataSet'!AF7) -> 0 | AB7: =IF('Raw DataSet'!AG7="","Unknown",'Raw DataSet'!AG7) -> 8 | AC7: =IF('Raw DataSet'!AH7="","Unknown",'Raw DataSet'!AH7) -> 2 | AD7: =IF('Raw DataSet'!AI7="","Unknown",'Raw DataSet'!AI7) -> 7 | AE7: =IF('Raw DataSet'!AJ7="","Unknown",'Raw DataSet'!AJ7) -> 7 | AF7: =IF('Raw DataSet'!AK7="","Unknown",'Raw DataSet'!AK7) -> 3 | AG7: =IF('Raw DataSet'!AL7="","Unknown",'Raw DataSet'!AL7) -> 6
A8: =IF('Raw DataSet'!I8="","Unknown",'Raw DataSet'!I8) -> 10 | B8: =IF('Raw DataSet'!H8="", "Unknown", 'Raw DataSet'!H8) -> STAFF-7 | C8: =IF('Raw DataSet'!J8="","Unknow",'Raw DataSet'!J8) -> Female | D8: =IF('Raw DataSet'!G8="","Unknown",'Raw DataSet'!G8) -> Medical | E8: =IF('Raw DataSet'!R8="","Unknown",'Raw DataSet'!R8) -> Bachelor's Degree | F8: =IF('Raw DataSet'!L8="","Unknown",'Raw DataSet'!L8) -> Married | G8: =IF('Raw DataSet'!P8="","Unknown",'Raw DataSet'!P8) -> 59 | H8: {=_xlfn.IFS(G8<24, "Under 25",G8<35, "25-34",G8<45, "35-44",G8<55, "45-54",TRUE, "Over 55")} -> Over 55 | I8: =IF('Raw DataSet'!F8="","Unknown",'Raw DataSet'!F8) -> R&D | J8: =IF('Raw DataSet'!K8="","Unknown",'Raw DataSet'!K8) -> Laboratory Technician | K8: =IF('Raw DataSet'!Q8="","Unknown",'Raw DataSet'!Q8) -> 3 | L8: {=_xlfn.IFS(K8<10,"0-9",K8<20,"10-19",TRUE,"20+")} -> 0-9 | M8: ='Raw DataSet'!A8 -> No | N8: =IF(M8="Yes",1,0) -> 0 | O8: =IF('Raw DataSet'!W8="","Unknown",'Raw DataSet'!W8) -> 64800 | P8: =IF(O8 <= QUARTILE($O:$O, 1), "Low", IF(O8 <= QUARTILE($O:$O, 3), "Medium", "High")) -> Medium | Q8: =IF('Raw DataSet'!M8="","Unknown",'Raw DataSet'!M8) -> Yes | R8: =IF('Raw DataSet'!T8="","Unknown",'Raw DataSet'!T8) -> 3 | S8: =IF('Raw DataSet'!Y8="","Unknown",'Raw DataSet'!Y8) -> 4 | T8: =IF('Raw DataSet'!Z8="","Unknown",'Raw DataSet'!Z8) -> 1 | U8: =IF('Raw DataSet'!AA8="","Unknown",'Raw DataSet'!AA8) -> 1 | V8: =IF('Raw DataSet'!AB8="","Unknown",'Raw DataSet'!AB8) -> 4 | W8: =IF('Raw DataSet'!AC8="","Unknown",'Raw DataSet'!AC8) -> 20 | X8: {=_xlfn.IFS(W8<15,"Under 15", W8<20,"15-19", TRUE,"Over 20")} -> Over 20 | Y8: =IF('Raw DataSet'!AD8="","Unknown",'Raw DataSet'!AD8) -> 4 | Z8: =IF('Raw DataSet'!AE8="","Unknown",'Raw DataSet'!AE8) -> 1 | AA8: =IF('Raw DataSet'!AF8="","Unknown",'Raw DataSet'!AF8) -> 3 | AB8: =IF('Raw DataSet'!AG8="","Unknown",'Raw DataSet'!AG8) -> 12 | AC8: =IF('Raw DataSet'!AH8="","Unknown",'Raw DataSet'!AH8) -> 2 | AD8: =IF('Raw DataSet'!AI8="","Unknown",'Raw DataSet'!AI8) -> 1 | AE8: =IF('Raw DataSet'!AJ8="","Unknown",'Raw DataSet'!AJ8) -> 0 | AF8: =IF('Raw DataSet'!AK8="","Unknown",'Raw DataSet'!AK8) -> 0 | AG8: =IF('Raw DataSet'!AL8="","Unknown",'Raw DataSet'!AL8) -> 0
A9: =IF('Raw DataSet'!I9="","Unknown",'Raw DataSet'!I9) -> 11 | B9: =IF('Raw DataSet'!H9="", "Unknown", 'Raw DataSet'!H9) -> STAFF-8 | C9: =IF('Raw DataSet'!J9="","Unknow",'Raw DataSet'!J9) -> Male | D9: =IF('Raw DataSet'!G9="","Unknown",'Raw DataSet'!G9) -> Life Sciences | E9: =IF('Raw DataSet'!R9="","Unknown",'Raw DataSet'!R9) -> High School | F9: =IF('Raw DataSet'!L9="","Unknown",'Raw DataSet'!L9) -> Divorced | G9: =IF('Raw DataSet'!P9="","Unknown",'Raw DataSet'!P9) -> 30 | H9: {=_xlfn.IFS(G9<24, "Under 25",G9<35, "25-34",G9<45, "35-44",G9<55, "45-54",TRUE, "Over 55")} -> 25-34 | I9: =IF('Raw DataSet'!F9="","Unknown",'Raw DataSet'!F9) -> R&D | J9: =IF('Raw DataSet'!K9="","Unknown",'Raw DataSet'!K9) -> Laboratory Technician | K9: =IF('Raw DataSet'!Q9="","Unknown",'Raw DataSet'!Q9) -> 24 | L9: {=_xlfn.IFS(K9<10,"0-9",K9<20,"10-19",TRUE,"20+")} -> 20+ | M9: ='Raw DataSet'!A9 -> No | N9: =IF(M9="Yes",1,0) -> 0 | O9: =IF('Raw DataSet'!W9="","Unknown",'Raw DataSet'!W9) -> 53600 | P9: =IF(O9 <= QUARTILE($O:$O, 1), "Low", IF(O9 <= QUARTILE($O:$O, 3), "Medium", "High")) -> Medium | Q9: =IF('Raw DataSet'!M9="","Unknown",'Raw DataSet'!M9) -> No | R9: =IF('Raw DataSet'!T9="","Unknown",'Raw DataSet'!T9) -> 4 | S9: =IF('Raw DataSet'!Y9="","Unknown",'Raw DataSet'!Y9) -> 3 | T9: =IF('Raw DataSet'!Z9="","Unknown",'Raw DataSet'!Z9) -> 1 | U9: =IF('Raw DataSet'!AA9="","Unknown",'Raw DataSet'!AA9) -> 3 | V9: =IF('Raw DataSet'!AB9="","Unknown",'Raw DataSet'!AB9) -> 1 | W9: =IF('Raw DataSet'!AC9="","Unknown",'Raw DataSet'!AC9) -> 22 | X9: {=_xlfn.IFS(W9<15,"Under 15", W9<20,"15-19", TRUE,"Over 20")} -> Over 20 | Y9: =IF('Raw DataSet'!AD9="","Unknown",'Raw DataSet'!AD9) -> 4 | Z9: =IF('Raw DataSet'!AE9="","Unknown",'Raw DataSet'!AE9) -> 2 | AA9: =IF('Raw DataSet'!AF9="","Unknown",'Raw DataSet'!AF9) -> 1 | AB9: =IF('Raw DataSet'!AG9="","Unknown",'Raw DataSet'!AG9) -> 1 | AC9: =IF('Raw DataSet'!AH9="","Unknown",'Raw DataSet'!AH9) -> 3 | AD9: =IF('Raw DataSet'!AI9="","Unknown",'Raw DataSet'!AI9) -> 1 | AE9: =IF('Raw DataSet'!AJ9="","Unknown",'Raw DataSet'!AJ9) -> 0 | AF9: =IF('Raw DataSet'!AK9="","Unknown",'Raw DataSet'!AK9) -> 0 | AG9: =IF('Raw DataSet'!AL9="","Unknown",'Raw DataSet'!AL9) -> 0
A10: =IF('Raw DataSet'!I10="","Unknown",'Raw DataSet'!I10) -> 12 | B10: =IF('Raw DataSet'!H10="", "Unknown", 'Raw DataSet'!H10) -> STAFF-9 | C10: =IF('Raw DataSet'!J10="","Unknow",'Raw DataSet'!J10) -> Male | D10: =IF('Raw DataSet'!G10="","Unknown",'Raw DataSet'!G10) -> Life Sciences | E10: =IF('Raw DataSet'!R10="","Unknown",'Raw DataSet'!R10) -> Bachelor's Degree | F10: =IF('Raw DataSet'!L10="","Unknown",'Raw DataSet'!L10) -> Single | G10: =IF('Raw DataSet'!P10="","Unknown",'Raw DataSet'!P10) -> 38 | H10: {=_xlfn.IFS(G10<24, "Under 25",G10<35, "25-34",G10<45, "35-44",G10<55, "45-54",TRUE, "Over 55")} -> 35-44 | I10: =IF('Raw DataSet'!F10="","Unknown",'Raw DataSet'!F10) -> R&D | J10: =IF('Raw DataSet'!K10="","Unknown",'Raw DataSet'!K10) -> Manufacturing Director | K10: =IF('Raw DataSet'!Q10="","Unknown",'Raw DataSet'!Q10) -> 23 | L10: {=_xlfn.IFS(K10<10,"0-9",K10<20,"10-19",TRUE,"20+")} -> 20+ | M10: ='Raw DataSet'!A10 -> No | N10: =IF(M10="Yes",1,0) -> 0 | O10: =IF('Raw DataSet'!W10="","Unknown",'Raw DataSet'!W10) -> 35200 | P10: =IF(O10 <= QUARTILE($O:$O, 1), "Low", IF(O10 <= QUARTILE($O:$O, 3), "Medium", "High")) -> Low | Q10: =IF('Raw DataSet'!M10="","Unknown",'Raw DataSet'!M10) -> No | R10: =IF('Raw DataSet'!T10="","Unknown",'Raw DataSet'!T10) -> 4 | S10: =IF('Raw DataSet'!Y10="","Unknown",'Raw DataSet'!Y10) -> 2 | T10: =IF('Raw DataSet'!Z10="","Unknown",'Raw DataSet'!Z10) -> 3 | U10: =IF('Raw DataSet'!AA10="","Unknown",'Raw DataSet'!AA10) -> 3 | V10: =IF('Raw DataSet'!AB10="","Unknown",'Raw DataSet'!AB10) -> 0 | W10: =IF('Raw DataSet'!AC10="","Unknown",'Raw DataSet'!AC10) -> 21 | X10: {=_xlfn.IFS(W10<15,"Under 15", W10<20,"15-19", TRUE,"Over 20")} -> Over 20 | Y10: =IF('Raw DataSet'!AD10="","Unknown",'Raw DataSet'!AD10) -> 4 | Z10: =IF('Raw DataSet'!AE10="","Unknown",'Raw DataSet'!AE10) -> 2 | AA10: =IF('Raw DataSet'!AF10="","Unknown",'Raw DataSet'!AF10) -> 0 | AB10: =IF('Raw DataSet'!AG10="","Unknown",'Raw DataSet'!AG10) -> 10 | AC10: =IF('Raw DataSet'!AH10="","Unknown",'Raw DataSet'!AH10) -> 3 | AD10: =IF('Raw DataSet'!AI10="","Unknown",'Raw DataSet'!AI10) -> 9 | AE10: =IF('Raw DataSet'!AJ10="","Unknown",'Raw DataSet'!AJ10) -> 7 | AF10: =IF('Raw DataSet'!AK10="","Unknown",'Raw DataSet'!AK10) -> 1 | AG10: =IF('Raw DataSet'!AL10="","Unknown",'Raw DataSet'!AL10) -> 8
A11: =IF('Raw DataSet'!I11="","Unknown",'Raw DataSet'!I11) -> 13 | B11: =IF('Raw DataSet'!H11="", "Unknown", 'Raw DataSet'!H11) -> STAFF-10 | C11: =IF('Raw DataSet'!J11="","Unknow",'Raw DataSet'!J11) -> Male | D11: =IF('Raw DataSet'!G11="","Unknown",'Raw DataSet'!G11) -> Medical | E11: =IF('Raw DataSet'!R11="","Unknown",'Raw DataSet'!R11) -> Bachelor's Degree | F11: =IF('Raw DataSet'!L11="","Unknown",'Raw DataSet'!L11) -> Married | G11: =IF('Raw DataSet'!P11="","Unknown",'Raw DataSet'!P11) -> 36 | H11: {=_xlfn.IFS(G11<24, "Under 25",G11<35, "25-34",G11<45, "35-44",G11<55, "45-54",TRUE, "Over 55")} -> 35-44 | I11: =IF('Raw DataSet'!F11="","Unknown",'Raw DataSet'!F11) -> R&D | J11: =IF('Raw DataSet'!K11="","Unknown",'Raw DataSet'!K11) -> Healthcare Representative | K11: =IF('Raw DataSet'!Q11="","Unknown",'Raw DataSet'!Q11) -> 27 | L11: {=_xlfn.IFS(K11<10,"0-9",K11<20,"10-19",TRUE,"20+")} -> 20+ | M11: ='Raw DataSet'!A11 -> No | N11: =IF(M11="Yes",1,0) -> 0 | O11: =IF('Raw DataSet'!W11="","Unknown",'Raw DataSet'!W11) -> 75200 | P11: =IF(O11 <= QUARTILE($O:$O, 1), "Low", IF(O11 <= QUARTILE($O:$O, 3), "Medium", "High")) -> High | Q11: =IF('Raw DataSet'!M11="","Unknown",'Raw DataSet'!M11) -> No | R11: =IF('Raw DataSet'!T11="","Unknown",'Raw DataSet'!T11) -> 3 | S11: =IF('Raw DataSet'!Y11="","Unknown",'Raw DataSet'!Y11) -> 3 | T11: =IF('Raw DataSet'!Z11="","Unknown",'Raw DataSet'!Z11) -> 2 | U11: =IF('Raw DataSet'!AA11="","Unknown",'Raw DataSet'!AA11) -> 3 | V11: =IF('Raw DataSet'!AB11="","Unknown",'Raw DataSet'!AB11) -> 6 | W11: =IF('Raw DataSet'!AC11="","Unknown",'Raw DataSet'!AC11) -> 13 | X11: {=_xlfn.IFS(W11<15,"Under 15", W11<20,"15-19", TRUE,"Over 20")} -> Under 15 | Y11: =IF('Raw DataSet'!AD11="","Unknown",'Raw DataSet'!AD11) -> 3 | Z11: =IF('Raw DataSet'!AE11="","Unknown",'Raw DataSet'!AE11) -> 2 | AA11: =IF('Raw DataSet'!AF11="","Unknown",'Raw DataSet'!AF11) -> 2 | AB11: =IF('Raw DataSet'!AG11="","Unknown",'Raw DataSet'!AG11) -> 17 | AC11: =IF('Raw DataSet'!AH11="","Unknown",'Raw DataSet'!AH11) -> 2 | AD11: =IF('Raw DataSet'!AI11="","Unknown",'Raw DataSet'!AI11) -> 7 | AE11: =IF('Raw DataSet'!AJ11="","Unknown",'Raw DataSet'!AJ11) -> 7 | AF11: =IF('Raw DataSet'!AK11="","Unknown",'Raw DataSet'!AK11) -> 7 | AG11: =IF('Raw DataSet'!AL11="","Unknown",'Raw DataSet'!AL11) -> 7
A12: =IF('Raw DataSet'!I12="","Unknown",'Raw DataSet'!I12) -> 14 | B12: =IF('Raw DataSet'!H12="", "Unknown", 'Raw DataSet'!H12) -> STAFF-11 | C12: =IF('Raw DataSet'!J12="","Unknow",'Raw DataSet'!J12) -> Male | D12: =IF('Raw DataSet'!G12="","Unknown",'Raw DataSet'!G12) -> Medical | E12: =IF('Raw DataSet'!R12="","Unknown",'Raw DataSet'!R12) -> Bachelor's Degree | F12: =IF('Raw DataSet'!L12="","Unknown",'Raw DataSet'!L12) -> Married | G12: =IF('Raw DataSet'!P12="","Unknown",'Raw DataSet'!P12) -> 35 | H12: {=_xlfn.IFS(G12<24, "Under 25",G12<35, "25-34",G12<45, "35-44",G12<55, "45-54",TRUE, "Over 55")} -> 35-44 | I12: =IF('Raw DataSet'!F12="","Unknown",'Raw DataSet'!F12) -> R&D | J12: =IF('Raw DataSet'!K12="","Unknown",'Raw DataSet'!K12) -> Laboratory Technician | K12: =IF('Raw DataSet'!Q12="","Unknown",'Raw DataSet'!Q12) -> 16 | L12: {=_xlfn.IFS(K12<10,"0-9",K12<20,"10-19",TRUE,"20+")} -> 10-19 | M12: ='Raw DataSet'!A12 -> No | N12: =IF(M12="Yes",1,0) -> 0 | O12: =IF('Raw DataSet'!W12="","Unknown",'Raw DataSet'!W12) -> 67200 | P12: =IF(O12 <= QUARTILE($O:$O, 1), "Low", IF(O12 <= QUARTILE($O:$O, 3), "Medium", "High")) -> Medium | Q12: =IF('Raw DataSet'!M12="","Unknown",'Raw DataSet'!M12) -> No | R12: =IF('Raw DataSet'!T12="","Unknown",'Raw DataSet'!T12) -> 1 | S12: =IF('Raw DataSet'!Y12="","Unknown",'Raw DataSet'!Y12) -> 4 | T12: =IF('Raw DataSet'!Z12="","Unknown",'Raw DataSet'!Z12) -> 1 | U12: =IF('Raw DataSet'!AA12="","Unknown",'Raw DataSet'!AA12) -> 2 | V12: =IF('Raw DataSet'!AB12="","Unknown",'Raw DataSet'!AB12) -> 0 | W12: =IF('Raw DataSet'!AC12="","Unknown",'Raw DataSet'!AC12) -> 13 | X12: {=_xlfn.IFS(W12<15,"Under 15", W12<20,"15-19", TRUE,"Over 20")} -> Under 15 | Y12: =IF('Raw DataSet'!AD12="","Unknown",'Raw DataSet'!AD12) -> 3 | Z12: =IF('Raw DataSet'!AE12="","Unknown",'Raw DataSet'!AE12) -> 3 | AA12: =IF('Raw DataSet'!AF12="","Unknown",'Raw DataSet'!AF12) -> 1 | AB12: =IF('Raw DataSet'!AG12="","Unknown",'Raw DataSet'!AG12) -> 6 | AC12: =IF('Raw DataSet'!AH12="","Unknown",'Raw DataSet'!AH12) -> 3 | AD12: =IF('Raw DataSet'!AI12="","Unknown",'Raw DataSet'!AI12) -> 5 | AE12: =IF('Raw DataSet'!AJ12="","Unknown",'Raw DataSet'!AJ12) -> 4 | AF12: =IF('Raw DataSet'!AK12="","Unknown",'Raw DataSet'!AK12) -> 0 | AG12: =IF('Raw DataSet'!AL12="","Unknown",'Raw DataSet'!AL12) -> 3
A13: =IF('Raw DataSet'!I13="","Unknown",'Raw DataSet'!I13) -> 15 | B13: =IF('Raw DataSet'!H13="", "Unknown", 'Raw DataSet'!H13) -> STAFF-12 | C13: =IF('Raw DataSet'!J13="","Unknow",'Raw DataSet'!J13) -> Female | D13: =IF('Raw DataSet'!G13="","Unknown",'Raw DataSet'!G13) -> Life Sciences | E13: =IF('Raw DataSet'!R13="","Unknown",'Raw DataSet'!R13) -> Associates Degree | F13: =IF('Raw DataSet'!L13="","Unknown",'Raw DataSet'!L13) -> Single | G13: =IF('Raw DataSet'!P13="","Unknown",'Raw DataSet'!P13) -> 29 | H13: {=_xlfn.IFS(G13<24, "Under 25",G13<35, "25-34",G13<45, "35-44",G13<55, "45-54",TRUE, "Over 55")} -> 25-34 | I13: =IF('Raw DataSet'!F13="","Unknown",'Raw DataSet'!F13) -> R&D | J13: =IF('Raw DataSet'!K13="","Unknown",'Raw DataSet'!K13) -> Laboratory Technician | K13: =IF('Raw DataSet'!Q13="","Unknown",'Raw DataSet'!Q13) -> 15 | L13: {=_xlfn.IFS(K13<10,"0-9",K13<20,"10-19",TRUE,"20+")} -> 10-19 | M13: ='Raw DataSet'!A13 -> No | N13: =IF(M13="Yes",1,0) -> 0 | O13: =IF('Raw DataSet'!W13="","Unknown",'Raw DataSet'!W13) -> 39200 | P13: =IF(O13 <= QUARTILE($O:$O, 1), "Low", IF(O13 <= QUARTILE($O:$O, 3), "Medium", "High")) -> Medium | Q13: =IF('Raw DataSet'!M13="","Unknown",'Raw DataSet'!M13) -> Yes | R13: =IF('Raw DataSet'!T13="","Unknown",'Raw DataSet'!T13) -> 4 | S13: =IF('Raw DataSet'!Y13="","Unknown",'Raw DataSet'!Y13) -> 2 | T13: =IF('Raw DataSet'!Z13="","Unknown",'Raw DataSet'!Z13) -> 2 | U13: =IF('Raw DataSet'!AA13="","Unknown",'Raw DataSet'!AA13) -> 3 | V13: =IF('Raw DataSet'!AB13="","Unknown",'Raw DataSet'!AB13) -> 0 | W13: =IF('Raw DataSet'!AC13="","Unknown",'Raw DataSet'!AC13) -> 12 | X13: {=_xlfn.IFS(W13<15,"Under 15", W13<20,"15-19", TRUE,"Over 20")} -> Under 15 | Y13: =IF('Raw DataSet'!AD13="","Unknown",'Raw DataSet'!AD13) -> 3 | Z13: =IF('Raw DataSet'!AE13="","Unknown",'Raw DataSet'!AE13) -> 4 | AA13: =IF('Raw DataSet'!AF13="","Unknown",'Raw DataSet'!AF13) -> 0 | AB13: =IF('Raw DataSet'!AG13="","Unknown",'Raw DataSet'!AG13) -> 10 | AC13: =IF('Raw DataSet'!AH13="","Unknown",'Raw DataSet'!AH13) -> 3 | AD13: =IF('Raw DataSet'!AI13="","Unknown",'Raw DataSet'!AI13) -> 9 | AE13: =IF('Raw DataSet'!AJ13="","Unknown",'Raw DataSet'!AJ13) -> 5 | AF13: =IF('Raw DataSet'!AK13="","Unknown",'Raw DataSet'!AK13) -> 0 | AG13: =IF('Raw DataSet'!AL13="","Unknown",'Raw DataSet'!AL13) -> 8
... A2926: =IF('Raw DataSet'!I2926="","Unknown",'Raw DataSet'!I2926) -> 3333 | B2926: =IF('Raw DataSet'!H2926="", "Unknown", 'Raw DataSet'!H2926) -> STAFF-2925 | C2926: =IF('Raw DataSet'!J2926="","Unknow",'Raw DataSet'!J2926) -> Male | D2926: =IF('Raw DataSet'!G2926="","Unknown",'Raw DataSet'!G2926) -> Life Sciences | E2926: =IF('Raw DataSet'!R2926="","Unknown",'Raw DataSet'!R2926) -> Bachelor's Degree | F2926: =IF('Raw DataSet'!L2926="","Unknown",'Raw DataSet'!L2926) -> Divorced | G2926: =IF('Raw DataSet'!P2926="","Unknown",'Raw DataSet'!P2926) -> 23 | H2926: {=_xlfn.IFS(G2926<24, "Under 25",G2926<35, "25-34",G2926<45, "35-44",G2926<55, "45-54",TRUE, "Over 55")} -> Under 25 | I2926: =IF('Raw DataSet'!F2926="","Unknown",'Raw DataSet'!F2926) -> Sales | J2926: =IF('Raw DataSet'!K2926="","Unknown",'Raw DataSet'!K2926) -> Sales Representative | K2926: =IF('Raw DataSet'!Q2926="","Unknown",'Raw DataSet'!Q2926) -> 7 | L2926: {=_xlfn.IFS(K2926<10,"0-9",K2926<20,"10-19",TRUE,"20+")} -> 0-9 | M2926: ='Raw DataSet'!A2926 -> Yes | N2926: =IF(M2926="Yes",1,0) -> 1 | O2926: =IF('Raw DataSet'!W2926="","Unknown",'Raw DataSet'!W2926) -> 79200 | P2926: =IF(O2926 <= QUARTILE($O:$O, 1), "Low", IF(O2926 <= QUARTILE($O:$O, 3), "Medium", "High")) -> High | Q2926: =IF('Raw DataSet'!M2926="","Unknown",'Raw DataSet'!M2926) -> Yes | R2926: =IF('Raw DataSet'!T2926="","Unknown",'Raw DataSet'!T2926) -> 3 | S2926: =IF('Raw DataSet'!Y2926="","Unknown",'Raw DataSet'!Y2926) -> 3 | T2926: =IF('Raw DataSet'!Z2926="","Unknown",'Raw DataSet'!Z2926) -> 1 | U2926: =IF('Raw DataSet'!AA2926="","Unknown",'Raw DataSet'!AA2926) -> 4 | V2926: =IF('Raw DataSet'!AB2926="","Unknown",'Raw DataSet'!AB2926) -> 1 | W2926: =IF('Raw DataSet'!AC2926="","Unknown",'Raw DataSet'!AC2926) -> 21 | X2926: {=_xlfn.IFS(W2926<15,"Under 15", W2926<20,"15-19", TRUE,"Over 20")} -> Over 20 | Y2926: =IF('Raw DataSet'!AD2926="","Unknown",'Raw DataSet'!AD2926) -> 4 | Z2926: =IF('Raw DataSet'!AE2926="","Unknown",'Raw DataSet'!AE2926) -> 2 | AA2926: =IF('Raw DataSet'!AF2926="","Unknown",'Raw DataSet'!AF2926) -> 1 | AB2926: =IF('Raw DataSet'!AG2926="","Unknown",'Raw DataSet'!AG2926) -> 3 | AC2926: =IF('Raw DataSet'!AH2926="","Unknown",'Raw DataSet'!AH2926) -> 3 | AD2926: =IF('Raw DataSet'!AI2926="","Unknown",'Raw DataSet'!AI2926) -> 3 | AE2926: =IF('Raw DataSet'!AJ2926="","Unknown",'Raw DataSet'!AJ2926) -> 2 | AF2926: =IF('Raw DataSet'!AK2926="","Unknown",'Raw DataSet'!AK2926) -> 0 | AG2926: =IF('Raw DataSet'!AL2926="","Unknown",'Raw DataSet'!AL2926) -> 2

Sheet Job & Organizational Factors
C8: Attrition | D8: Yes
C10: Department | D10: Count of Attrition
C11: HR | D11: 24
C12: R&D | D12: 264
C13: Sales | D13: 185
C14: Grand Total | D14: 473
C27: Attrition | D27: Yes
C29: Job Role | D29: Count of Attrition
C30: Healthcare Representative | D30: 18
C31: Human Resources | D31: 24
C32: Laboratory Technician | D32: 122
C33: Manager | D33: 10
C34: Manufacturing Director | D34: 20
C35: Research Director | D35: 4
C36: Research Scientist | D36: 94
C37: Sales Executive | D37: 113
C38: Sales Representative | D38: 68
C39: Grand Total | D39: 473
C52: Attrition | D52: Yes
C54: Years At Company | D54: Count of Attrition
C55: 0 | D55: 31
C56: 1 | D56: 118
C57: 2 | D57: 54
C58: 3 | D58: 42
C59: 4 | D59: 37
C60: 5 | D60: 42
C61: 6 | D61: 17
C62: 7 | D62: 22
C63: 8 | D63: 18
C64: 9 | D64: 16
C65: 10 | D65: 36
C66: 11 | D66: 4
... C82: 40 | D82: 2
C83: Grand Total | D83: 473
C100: Attrition | D100: Yes
C102: Education | D102: Count of Attrition
C103: Associates Degree | D103: 86
C104: Bachelor's Degree | D104: 199
C105: Doctoral Degree | D105: 10
C106: High School | D106: 62
...

Sheet Demographic Factors
C6: Attrition | D6: Yes
C8: Age Group | D8: Count of Attrition
C9: 25-34 | D9: 237
C10: 35-44 | D10: 100
C11: 45-54 | D11: 50
C12: Over 55 | D12: 22
C13: Under 25 | D13: 64
C14: Grand Total | D14: 473
C27: Attrition | D27: Yes
C29: Gender | D29: Count of Attrition
C30: Female | D30: 173
C31: Male | D31: 300
C32: Grand Total | D32: 473
C45: Attrition | D45: Yes
C47: Marital Status | D47: Count of Attrition
C48: Divorced | D48: 68
C49: Married | D49: 168
C50: Single | D50: 237
C51: Grand Total | D51: 473
C63: Attrition | D63: Yes
C65: Distance Group | D65: Count of Attrition
C66: 0-9 | D66: 266
C67: 10-19 | D67: 110
C68: 20+ | D68: 97
C69: Grand Total | D69: 473

Sheet Work Experience & Satisfaction
C6: Attrition | D6: Yes
C8: Job Satisfaction | D8: Count of Attrition
C9: 1 | D9: 132
C10: 2 | D10: 92
C11: 3 | D11: 144
C12: 4 | D12: 105
C13: Grand Total | D13: 473
C26: Attrition | D26: Yes
C28: Environment Satisfaction | D28: Count of Attrition
C29: 1 | D29: 144
C30: 2 | D30: 85
C31: 3 | D31: 125
C32: 4 | D32: 119
C33: Grand Total | D33: 473
C46: Attrition | D46: Yes
C48: Over Time | D48: Count of Attrition
C49: No | D49: 220
C50: Yes | D50: 253
C51: Grand Total | D51: 473
C64: Attrition | D64: Yes
C66: Performance Rating | D66: Count of Attrition
C67: 3 | D67: 397
C68: 4 | D68: 76
C69: Grand Total | D69: 473

Sheet Compensation
C8: Count of Attrition | D8: Attrition
C9: Income Group | D9: No | E9: Yes | F9: Grand Total
C10: High | D10: 568 | E10: 110 | F10: 678
C11: Low | D11: 633 | E11: 114 | F11: 747
C12: Medium | D12: 1251 | E12: 249 | F12: 1500
C13: Grand Total | D13: 2452 | E13: 473 | F13: 2925
C26: Attrition | D26: Yes
C28: Salary Hike Group | D28: Count of Attrition
C29: 15-19 | D29: 135
C30: Over 20 | D30: 76
C31: Under 15 | D31: 262
C32: Grand Total | D32: 473

Sheet Analysis
A1: Job and Organizational Factors | P1: Demographic Factors
A25: Attrition is highest in R&D, technical roles, and among employees with low tenure (0–2 years). It is significantly lower in HR, management roles, and employees with higher educational qualifications or longer service durations | P25: Younger employees (especially 25–34), single employees, and males show higher attrition. Attrition is also unexpectedly higher among short-distance commuters, likely because they are younger or in early-career roles. These patterns highlight the impact of age, gender, marital status, and commute on employee turnover
A31: Work Experiencce and Satisfaction | P31: Compensation
P44: Employees earning lower salaries are more likely to leave, and salary hikes by themselves are not currently leading to improved retention. Broader engagement, career growth, and workplace satisfaction factors may need attention to reduce attrition effectively
P48: At-Risk Employees
P49: Employees with low job satisfaction—especially those rating it “1”—show the highest attrition. Current employees reporting low satisfaction are at the greatest risk of leaving.
P51: Employees who give a low rating to their work environment (rating “1”) have significantly higher attrition. Those dissatisfied with their workplace environment are at risk.
P53: Employees working overtime tend to leave more frequently. Current employees putting in overtime hours fall into a higher-risk category.
A55: Attrition is strongly influenced by an employee’s work experience and satisfaction level. Employees with low job or environment satisfaction, overtime workers, and average performers are most likely to leave. High performers also leave when they feel undervalued or encounter limited advancement opportunities. | P55: Employees aged 25–34 show the highest attrition rates compared to other age groups. Individuals within this age bracket are more likely to leave.
P57: Single employees experience higher attrition compared to married employees. Being single is associated with greater risk of leaving.
I64: Analysis for HR
I65: - Check in regularly with employees who seem disengaged to understand what they need. - Make the workplace better by listening to feedback and acting on it. - Support those working overtime by easing their load or rewarding their effort. - Offer growth and learning options, especially for younger employees.
